Traceback (most recent call last):
  File "C:\Users\S-FAMILY\AppData\Local\Programs\Python\Python39-32\lib\site-packages\llvmlite\binding\ffi.py", line 136, in __getattr__
    return self._fntab[name]
KeyError: 'LLVMPY_AddSymbol'

During handling of the above exception, another exception occurred:

Traceback (most recent call last):
  File "C:\Users\S-FAMILY\AppData\Local\Programs\Python\Python39-32\lib\site-packages\llvmlite\binding\ffi.py", line 117, in _load_lib
    self._lib_handle = ctypes.CDLL(str(lib_path))
  File "C:\Users\S-FAMILY\AppData\Local\Programs\Python\Python39-32\lib\ctypes\__init__.py", line 374, in __init__       
    self._handle = _dlopen(self._name, mode)
OSError: [WinError 193] %1 is not a valid Win32 application

The above exception was the direct cause of the following exception:

Traceback (most recent call last):
  File "c:\Users\S-FAMILY\Desktop\run\SAZOM.py", line 6, in <module>
    from rembg import remove
  File "C:\Users\S-FAMILY\AppData\Local\Programs\Python\Python39-32\lib\site-packages\rembg\__init__.py", line 5, in <module>
    from .bg import remove
  File "C:\Users\S-FAMILY\AppData\Local\Programs\Python\Python39-32\lib\site-packages\rembg\bg.py", line 17, in <module> 
    from pymatting.alpha.estimate_alpha_cf import estimate_alpha_cf
  File "C:\Users\S-FAMILY\AppData\Local\Programs\Python\Python39-32\lib\site-packages\pymatting\__init__.py", line 2, in 
<module>
    from pymatting.util import *
  File "C:\Users\S-FAMILY\AppData\Local\Programs\Python\Python39-32\lib\site-packages\pymatting\util\__init__.py", line 2, in <module>
    from pymatting.util.kdtree import KDTree, knn
  File "C:\Users\S-FAMILY\AppData\Local\Programs\Python\Python39-32\lib\site-packages\pymatting\util\kdtree.py", line 2, 
in <module>
    from numba import njit, prange
  File "C:\Users\S-FAMILY\AppData\Local\Programs\Python\Python39-32\lib\site-packages\numba\__init__.py", line 70, in <module>
    from numba.core import config
  File "C:\Users\S-FAMILY\AppData\Local\Programs\Python\Python39-32\lib\site-packages\numba\core\config.py", line 17, in 
<module>
    import llvmlite.binding as ll
  File "C:\Users\S-FAMILY\AppData\Local\Programs\Python\Python39-32\lib\site-packages\llvmlite\binding\__init__.py", line 4, in <module>
    from .dylib import *
  File "C:\Users\S-FAMILY\AppData\Local\Programs\Python\Python39-32\lib\site-packages\llvmlite\binding\dylib.py", line 36, in <module>
    ffi.lib.LLVMPY_AddSymbol.argtypes = [
  File "C:\Users\S-FAMILY\AppData\Local\Programs\Python\Python39-32\lib\site-packages\llvmlite\binding\ffi.py", line 139, in __getattr__
    cfn = getattr(self._lib, name)
  File "C:\Users\S-FAMILY\AppData\Local\Programs\Python\Python39-32\lib\site-packages\llvmlite\binding\ffi.py", line 131, in _lib
    self._load_lib()
  File "C:\Users\S-FAMILY\AppData\Local\Programs\Python\Python39-32\lib\site-packages\llvmlite\binding\ffi.py", line 125, in _load_lib
    raise OSError("Could not find/load shared object file") from e
OSError: Could not find/load shared object file
